2024-10-28 04:24:49,027 ERROR: Exception on / [GET] [in /home/runner/workspace/.pythonlibs/lib/python3.11/site-packages/flask/app.py:838]
Traceback (most recent call last):
  File "/home/runner/workspace/.pythonlibs/lib/python3.11/site-packages/flask/app.py", line 880, in full_dispatch_request
    rv = self.dispatch_request()
         ^^^^^^^^^^^^^^^^^^^^^^^
  File "/home/runner/workspace/.pythonlibs/lib/python3.11/site-packages/flask/app.py", line 854, in dispatch_request
    self.raise_routing_exception(req)
  File "/home/runner/workspace/.pythonlibs/lib/python3.11/site-packages/flask/app.py", line 463, in raise_routing_exception
    raise request.routing_exception  # type: ignore[misc]
    ^^^^^^^^^^^^^^^^^^^^^^^^^^^^^^^
  File "/home/runner/workspace/.pythonlibs/lib/python3.11/site-packages/flask/ctx.py", line 362, in match_request
    result = self.url_adapter.match(return_rule=True)  # type: ignore
             ^^^^^^^^^^^^^^^^^^^^^^^^^^^^^^^^^^^^^^^^
  File "/home/runner/workspace/.pythonlibs/lib/python3.11/site-packages/werkzeug/routing/map.py", line 629, in match
    raise NotFound() from None
werkzeug.exceptions.NotFound: 404 Not Found: The requested URL was not found on the server. If you entered the URL manually please check your spelling and try again.

During handling of the above exception, another exception occurred:

Traceback (most recent call last):
  File "/home/runner/workspace/.pythonlibs/lib/python3.11/site-packages/flask/app.py", line 1473, in wsgi_app
    response = self.full_dispatch_request()
               ^^^^^^^^^^^^^^^^^^^^^^^^^^^^
  File "/home/runner/workspace/.pythonlibs/lib/python3.11/site-packages/flask/app.py", line 882, in full_dispatch_request
    rv = self.handle_user_exception(e)
         ^^^^^^^^^^^^^^^^^^^^^^^^^^^^^
  File "/home/runner/workspace/.pythonlibs/lib/python3.11/site-packages/flask_cors/extension.py", line 194, in wrapped_function
    return cors_after_request(app.make_response(f(*args, **kwargs)))
                                                ^^^^^^^^^^^^^^^^^^
  File "/home/runner/workspace/.pythonlibs/lib/python3.11/site-packages/flask/app.py", line 765, in handle_user_exception
    return self.handle_http_exception(e)
           ^^^^^^^^^^^^^^^^^^^^^^^^^^^^^
  File "/home/runner/workspace/.pythonlibs/lib/python3.11/site-packages/flask/app.py", line 740, in handle_http_exception
    return self.ensure_sync(handler)(e)  # type: ignore[no-any-return]
           ^^^^^^^^^^^^^^^^^^^^^^^^^^^^
  File "/home/runner/workspace/app.py", line 197, in not_found_error
    logger.warning(f"404 error: {request.url}")
                                 ^^^^^^^
NameError: name 'request' is not defined
2024-10-28 04:25:46,628 INFO: No Redis URL configured, using simple cache [in /home/runner/workspace/app.py:140]
2024-10-28 04:25:51,553 INFO: Temporary files cleanup completed [in /home/runner/workspace/app.py:215]
2024-10-28 04:25:51,554 INFO: Expired sessions cleanup completed [in /home/runner/workspace/app.py:227]
2024-10-28 04:25:51,554 INFO: Application initialized successfully [in /home/runner/workspace/app.py:298]
2024-10-28 05:02:50,692 INFO: No Redis URL configured, using simple cache [in /home/runner/workspace/app.py:140]
2024-10-28 05:02:50,692 INFO: No Redis URL configured, using simple cache [in /home/runner/workspace/app.py:140]
2024-10-28 05:02:56,374 INFO: Temporary files cleanup completed [in /home/runner/workspace/app.py:215]
2024-10-28 05:02:56,375 INFO: Expired sessions cleanup completed [in /home/runner/workspace/app.py:227]
2024-10-28 05:02:56,375 INFO: Temporary files cleanup completed [in /home/runner/workspace/app.py:215]
2024-10-28 05:02:56,375 INFO: Application initialized successfully [in /home/runner/workspace/app.py:298]
2024-10-28 05:02:56,375 INFO: Expired sessions cleanup completed [in /home/runner/workspace/app.py:227]
2024-10-28 05:02:56,375 INFO: Application initialized successfully [in /home/runner/workspace/app.py:298]
2024-10-28 05:03:00,690 INFO: No Redis URL configured, using simple cache [in /home/runner/workspace/app.py:140]
2024-10-28 05:03:00,774 INFO: No Redis URL configured, using simple cache [in /home/runner/workspace/app.py:140]
2024-10-28 05:03:05,683 INFO: Temporary files cleanup completed [in /home/runner/workspace/app.py:215]
2024-10-28 05:03:05,683 INFO: Expired sessions cleanup completed [in /home/runner/workspace/app.py:227]
2024-10-28 05:03:05,684 INFO: Application initialized successfully [in /home/runner/workspace/app.py:298]
2024-10-28 05:03:05,729 INFO: Temporary files cleanup completed [in /home/runner/workspace/app.py:215]
2024-10-28 05:03:05,729 INFO: Expired sessions cleanup completed [in /home/runner/workspace/app.py:227]
2024-10-28 05:03:05,730 INFO: Application initialized successfully [in /home/runner/workspace/app.py:298]
